 (￣y▽￣)╭可能登录失败了手动登录一下吧
判断页面1成功 0失败  结果是=1
[<selenium.webdriver.remote.webelement.WebElement (session="8b3fbabae68662e9cac7f732a923cbd0", element="0.8357170853372495-1")>, <selenium.webdriver.remote.webelement.WebElement (session="8b3fbabae68662e9cac7f732a923cbd0", element="0.8357170853372495-2")>, <selenium.webdriver.remote.webelement.WebElement (session="8b3fbabae68662e9cac7f732a923cbd0", element="0.8357170853372495-3")>, <selenium.webdriver.remote.webelement.WebElement (session="8b3fbabae68662e9cac7f732a923cbd0", element="0.8357170853372495-4")>, <selenium.webdriver.remote.webelement.WebElement (session="8b3fbabae68662e9cac7f732a923cbd0", element="0.8357170853372495-5")>, <selenium.webdriver.remote.webelement.WebElement (session="8b3fbabae68662e9cac7f732a923cbd0", element="0.8357170853372495-6")>, <selenium.webdriver.remote.webelement.WebElement (session="8b3fbabae68662e9cac7f732a923cbd0", element="0.8357170853372495-7")>, <selenium.webdriver.remote.webelement.WebElement (session="8b3fbabae68662e9cac7f732a923cbd0", element="0.8357170853372495-8")>, <selenium.webdriver.remote.webelement.WebElement (session="8b3fbabae68662e9cac7f732a923cbd0", element="0.8357170853372495-9")>, <selenium.webdriver.remote.webelement.WebElement (session="8b3fbabae68662e9cac7f732a923cbd0", element="0.8357170853372495-10")>]
伦哥：好棒！第1次运行了
运行时间：2017-08-06 01:40:20
Traceback (most recent call last):
  File "test_repost_new.py", line 250, in <module>
    #        print('33333333')
  File "test_repost_new.py", line 216, in repost
  File "/Library/Frameworks/Python.framework/Versions/3.5/lib/python3.5/site-packages/selenium/webdriver/remote/webdriver.py", line 433, in find_element_by_class_name
  File "/Library/Frameworks/Python.framework/Versions/3.5/lib/python3.5/site-packages/selenium/webdriver/remote/webdriver.py", line 791, in find_element
  File "/Library/Frameworks/Python.framework/Versions/3.5/lib/python3.5/site-packages/selenium/webdriver/remote/webdriver.py", line 254, in execute
  File "/Library/Frameworks/Python.framework/Versions/3.5/lib/python3.5/site-packages/selenium/webdriver/remote/remote_connection.py", line 464, in execute
  File "/Library/Frameworks/Python.framework/Versions/3.5/lib/python3.5/site-packages/selenium/webdriver/remote/remote_connection.py", line 487, in _request
    self._conn.request(method, parsed_url.path, body, headers)
  File "/Library/Frameworks/Python.framework/Versions/3.5/lib/python3.5/http/client.py", line 1083, in request
    self._send_request(method, url, body, headers)
  File "/Library/Frameworks/Python.framework/Versions/3.5/lib/python3.5/http/client.py", line 1128, in _send_request
  File "/Library/Frameworks/Python.framework/Versions/3.5/lib/python3.5/http/client.py", line 1079, in endheaders
  File "/Library/Frameworks/Python.framework/Versions/3.5/lib/python3.5/http/client.py", line 911, in _send_output
  File "/Library/Frameworks/Python.framework/Versions/3.5/lib/python3.5/http/client.py", line 854, in send
  File "/Library/Frameworks/Python.framework/Versions/3.5/lib/python3.5/http/client.py", line 826, in connect
  File "/Library/Frameworks/Python.framework/Versions/3.5/lib/python3.5/socket.py", line 707, in create_connection
  File "/Library/Frameworks/Python.framework/Versions/3.5/lib/python3.5/socket.py", line 693, in create_connection
    sock = socket(af, socktype, proto)
  File "/Library/Frameworks/Python.framework/Versions/3.5/lib/python3.5/socket.py", line 134, in __init__
    _socket.socket.__init__(self, family, type, proto, fileno)
OSError: [Errno 23] Too many open files in system
