Traceback (most recent call last):
  File "my_repost.py", line 180, in <module>
    driver1 = initWork()
  File "my_repost.py", line 24, in initWork
    brower = webdriver.Chrome(chromedriver)
  File "/Library/Frameworks/Python.framework/Versions/3.5/lib/python3.5/site-packages/selenium/webdriver/chrome/webdriver.py", line 62, in __init__
    self.service.start()
  File "/Library/Frameworks/Python.framework/Versions/3.5/lib/python3.5/site-packages/selenium/webdriver/common/service.py", line 96, in start
    self.assert_process_still_running()
  File "/Library/Frameworks/Python.framework/Versions/3.5/lib/python3.5/site-packages/selenium/webdriver/common/service.py", line 109, in assert_process_still_running
    % (self.path, return_code)
selenium.common.exceptions.WebDriverException: Message: Service /Applications/Google Chrome.app/chromedriver unexpectedly exited. Status code was: 1

