 (￣y▽￣)╭可能登录失败了手动登录一下吧
判断页面1成功 0失败  结果是=1
[<selenium.webdriver.remote.webelement.WebElement (session="68670fd28480118e080fa5d128e18ee0", element="0.35452531906636975-1")>, <selenium.webdriver.remote.webelement.WebElement (session="68670fd28480118e080fa5d128e18ee0", element="0.35452531906636975-2")>, <selenium.webdriver.remote.webelement.WebElement (session="68670fd28480118e080fa5d128e18ee0", element="0.35452531906636975-3")>, <selenium.webdriver.remote.webelement.WebElement (session="68670fd28480118e080fa5d128e18ee0", element="0.35452531906636975-4")>, <selenium.webdriver.remote.webelement.WebElement (session="68670fd28480118e080fa5d128e18ee0", element="0.35452531906636975-5")>, <selenium.webdriver.remote.webelement.WebElement (session="68670fd28480118e080fa5d128e18ee0", element="0.35452531906636975-6")>, <selenium.webdriver.remote.webelement.WebElement (session="68670fd28480118e080fa5d128e18ee0", element="0.35452531906636975-7")>, <selenium.webdriver.remote.webelement.WebElement (session="68670fd28480118e080fa5d128e18ee0", element="0.35452531906636975-8")>, <selenium.webdriver.remote.webelement.WebElement (session="68670fd28480118e080fa5d128e18ee0", element="0.35452531906636975-9")>, <selenium.webdriver.remote.webelement.WebElement (session="68670fd28480118e080fa5d128e18ee0", element="0.35452531906636975-10")>]
伦哥：好棒！第1次运行了
运行时间：2017-08-06 01:39:19
Traceback (most recent call last):
  File "test_repost_new.py", line 250, in <module>
    #        print('33333333')
  File "test_repost_new.py", line 209, in repost
    browser.find_element_by_tag_name('body').send_keys(Keys.CONTROL + 't')
  File "/Library/Frameworks/Python.framework/Versions/3.5/lib/python3.5/site-packages/selenium/webdriver/remote/webdriver.py", line 409, in find_element_by_tag_name
    return self.find_element(by=By.TAG_NAME, value=name)
  File "/Library/Frameworks/Python.framework/Versions/3.5/lib/python3.5/site-packages/selenium/webdriver/remote/webdriver.py", line 791, in find_element
    'value': value})['value']
  File "/Library/Frameworks/Python.framework/Versions/3.5/lib/python3.5/site-packages/selenium/webdriver/remote/webdriver.py", line 254, in execute
    response = self.command_executor.execute(driver_command, params)
  File "/Library/Frameworks/Python.framework/Versions/3.5/lib/python3.5/site-packages/selenium/webdriver/remote/remote_connection.py", line 464, in execute
    return self._request(command_info[0], url, body=data)
  File "/Library/Frameworks/Python.framework/Versions/3.5/lib/python3.5/site-packages/selenium/webdriver/remote/remote_connection.py", line 487, in _request
    self._conn.request(method, parsed_url.path, body, headers)
  File "/Library/Frameworks/Python.framework/Versions/3.5/lib/python3.5/http/client.py", line 1083, in request
    self._send_request(method, url, body, headers)
  File "/Library/Frameworks/Python.framework/Versions/3.5/lib/python3.5/http/client.py", line 1128, in _send_request
    self.endheaders(body)
  File "/Library/Frameworks/Python.framework/Versions/3.5/lib/python3.5/http/client.py", line 1079, in endheaders
    self._send_output(message_body)
  File "/Library/Frameworks/Python.framework/Versions/3.5/lib/python3.5/http/client.py", line 911, in _send_output
    self.send(msg)
  File "/Library/Frameworks/Python.framework/Versions/3.5/lib/python3.5/http/client.py", line 854, in send
    self.connect()
  File "/Library/Frameworks/Python.framework/Versions/3.5/lib/python3.5/http/client.py", line 826, in connect
    (self.host,self.port), self.timeout, self.source_address)
  File "/Library/Frameworks/Python.framework/Versions/3.5/lib/python3.5/socket.py", line 707, in create_connection
    raise err
  File "/Library/Frameworks/Python.framework/Versions/3.5/lib/python3.5/socket.py", line 693, in create_connection
    sock = socket(af, socktype, proto)
  File "/Library/Frameworks/Python.framework/Versions/3.5/lib/python3.5/socket.py", line 134, in __init__
    _socket.socket.__init__(self, family, type, proto, fileno)
OSError: [Errno 23] Too many open files in system
