Traceback (most recent call last):
  File "test_repost_new.py", line 243, in <module>
    elems1 = handleLogin(driver1, usrname, pwd)
  File "test_repost_new.py", line 39, in handleLogin
    cookie1 = brower.get_cookies()
  File "/Library/Frameworks/Python.framework/Versions/3.5/lib/python3.5/site-packages/selenium/webdriver/remote/webdriver.py", line 661, in get_cookies
    return self.execute(Command.GET_ALL_COOKIES)['value']
  File "/Library/Frameworks/Python.framework/Versions/3.5/lib/python3.5/site-packages/selenium/webdriver/remote/webdriver.py", line 256, in execute
    self.error_handler.check_response(response)
  File "/Library/Frameworks/Python.framework/Versions/3.5/lib/python3.5/site-packages/selenium/webdriver/remote/errorhandler.py", line 194, in check_response
    raise exception_class(message, screen, stacktrace)
selenium.common.exceptions.WebDriverException: Message: chrome not reachable
  (Session info: chrome=60.0.3112.90)
  (Driver info: chromedriver=2.31.488774 (7e15618d1bf16df8bf0ecf2914ed1964a387ba0b),platform=Mac OS X 10.12.6 x86_64)

