[{'httpOnly': True, 'name': '_T_WM', 'expiry': 1504618134.53527, 'secure': False, 'domain': '.weibo.cn', 'path': '/', 'value': '8449f8d60d9f550baa075bb08a68b314'}]
 (￣y▽￣)╭可能登录失败了手动登录一下吧
判断页面1成功 0失败  结果是=1
伦哥：呜呜呜，13056792409----abc12345 这个号不能用啦 
Traceback (most recent call last):
  File "my_repost.py", line 187, in <module>
    cookie3 = driver1.get_cookies()
  File "/Library/Frameworks/Python.framework/Versions/3.5/lib/python3.5/site-packages/selenium/webdriver/remote/webdriver.py", line 661, in get_cookies
    return self.execute(Command.GET_ALL_COOKIES)['value']
  File "/Library/Frameworks/Python.framework/Versions/3.5/lib/python3.5/site-packages/selenium/webdriver/remote/webdriver.py", line 254, in execute
    response = self.command_executor.execute(driver_command, params)
  File "/Library/Frameworks/Python.framework/Versions/3.5/lib/python3.5/site-packages/selenium/webdriver/remote/remote_connection.py", line 464, in execute
    return self._request(command_info[0], url, body=data)
  File "/Library/Frameworks/Python.framework/Versions/3.5/lib/python3.5/site-packages/selenium/webdriver/remote/remote_connection.py", line 487, in _request
    self._conn.request(method, parsed_url.path, body, headers)
  File "/Library/Frameworks/Python.framework/Versions/3.5/lib/python3.5/http/client.py", line 1083, in request
    self._send_request(method, url, body, headers)
  File "/Library/Frameworks/Python.framework/Versions/3.5/lib/python3.5/http/client.py", line 1128, in _send_request
    self.endheaders(body)
  File "/Library/Frameworks/Python.framework/Versions/3.5/lib/python3.5/http/client.py", line 1079, in endheaders
    self._send_output(message_body)
  File "/Library/Frameworks/Python.framework/Versions/3.5/lib/python3.5/http/client.py", line 911, in _send_output
    self.send(msg)
  File "/Library/Frameworks/Python.framework/Versions/3.5/lib/python3.5/http/client.py", line 854, in send
    self.connect()
  File "/Library/Frameworks/Python.framework/Versions/3.5/lib/python3.5/http/client.py", line 826, in connect
    (self.host,self.port), self.timeout, self.source_address)
  File "/Library/Frameworks/Python.framework/Versions/3.5/lib/python3.5/socket.py", line 707, in create_connection
    raise err
  File "/Library/Frameworks/Python.framework/Versions/3.5/lib/python3.5/socket.py", line 698, in create_connection
    sock.connect(sa)
ConnectionRefusedError: [Errno 61] Connection refused
